Workbook

Sheet Example of Residential SS
A1: OWNER'S SWORN STATEMENT - Example of categories for the Construction of a Residential Home
K2: Title Company File #
B3: Owner: | F3: General Contractor Name: | K3: Phone #
B4: Address of | F4: Person Submitting: | K4: Email address
B5: Improvements: | G5: (authorized person signing sworn statement) | K5: Cell phone #
B7: State of Michigan | D7: ) | G7: (2) The following is a statement of each subcontractor and supplier, and laborer for whom payment of wages or fringe benefits and withholdings is due but unpaid, with whom the (contractor) (subcontractor) has (contracted) (subcontracted) for performance under the contract with the owner or lessee of the property, and the amounts due to the persons as of the date of this statement are correctly and fully set forth opposite their names. (3) The contractor has not procured material from, or subcontracted with, any person other than those set forth and owes no money for the improvement other than the sums set forth. (4) I make this statement as the (contractor) (subcontractor) or as ____________________ of the (contractor) (subcontractor) to represent to the owner or lessee of the property and his or her agents that the property is free from claims of construction liens, or the possibility of construction liens, except as specifically set forth in this statement except for claims of construction liens by laborers that may be provided under Section 109 of the Construction Lien Act, 1980 PA 497, MCL 570.1109.
D8: ) ss.
B9: County of : | D9: )
B11: =IF(G4=0,"",G4) | D11: (deponent), being sworn, states the following:
A12: (1) | B12: =+G3 -> 0 | D12: is the (contractor) (subcontractor) for an improvement to the following real
B13: property in | C13: =+C9 -> 0 | D13: County, Michigan described as follows:
B16: Name of Subcontractor, Supplier or Laborer | D16: Address of Subcontractor, Supplier or Laborer | E16: Telephone # | F16: Type of Improvement Furnished | G16: Total Contract Price | H16: Adjustment to Contract Amount ( +/ -) | I16: Adjusted Contract Price | J16: Amount Already Paid | K16: Current Request | L16: Balance to Complete
A17: 1 | F17: ARCHITECTURAL SERVICES | G17: 0 | H17: 0 | I17: =+G17+H17 -> 0 | L17: =+I17-J17-K17 -> 0
A18: 2 | F18: ENGINEERING SERVICES | G18: 0 | H18: 0 | I18: =+G18+H18 -> 0 | L18: =+I18-J18-K18 -> 0
A19: 3 | F19: EXCAVATING | G19: 0 | H19: 0 | I19: =+G19+H19 -> 0 | L19: =+I19-J19-K19 -> 0
A20: 4 | F20: SAND/GRAVEL/BACKFILL | G20: 0 | H20: 0 | I20: =+G20+H20 -> 0 | L20: =+I20-J20-K20 -> 0
A21: 5 | F21: BASEMENT WALLS | G21: 0 | H21: 0 | I21: =+G21+H21 -> 0 | L21: =+I21-J21-K21 -> 0
A22: 6 | F22: STRUCTURAL STEEL | G22: 0 | H22: 0 | I22: =+G22+H22 -> 0 | L22: =+I22-J22-K22 -> 0
A23: 7 | F23: ROUGH LUMBER/TRUSSES | G23: 0 | H23: 0 | I23: =+G23+H23 -> 0 | L23: =+I23-J23-K23 -> 0
A24: 8 | F24: FINISH LUMBER | G24: 0 | H24: 0 | I24: =+G24+H24 -> 0 | L24: =+I24-J24-K24 -> 0
A25: 9 | F25: ROUGH CARPENTRY | G25: 0 | H25: 0 | I25: =+G25+H25 -> 0 | L25: =+I25-J25-K25 -> 0
A26: 10 | F26: FINISH CARPENTRY | G26: 0 | H26: 0 | I26: =+G26+H26 -> 0 | L26: =+I26-J26-K26 -> 0
A27: 11 | F27: WINDOWS & DOORS | G27: 0 | H27: 0 | I27: =+G27+H27 -> 0 | L27: =+I27-J27-K27 -> 0
A28: 12 | F28: ROOFING LABOR / MATERIALS | G28: 0 | H28: 0 | I28: =+G28+H28 -> 0 | L28: =+I28-J28-K28 -> 0
... A46: 30 | F46: COUNTERTOPS | G46: 0 | H46: 0 | I46: =+G46+H46 -> 0 | L46: =+I46-J46-K46 -> 0
F47: SUBTOTALS | G47: =SUM(G17:G46) -> 0 | H47: =SUM(H17:H46) -> 0 | I47: =SUM(I17:I46) -> 0 | J47: =SUM(J17:J46) -> 0 | K47: =SUM(K17:K46) -> 0 | L47: =SUM(L17:L46) -> 0
B48: WARNING TO OWNER OR LESSEE: An owner or lessee of the property may not rely on this sworn statement to avoid the claim of a subcontractor, supplier, or laborer who has provided a Notice of Furnishing or a laborer who may provide a Notice of Furnishing under Section 109 of the Construction Lien Act, 1980 PA 497, MCL 570.1109, to the designee or to the owner or lessee if the designee is not named or has died.
B52: Name of Subcontractor, Supplier or Laborer | D52: Address of Subcontractor, Supplier or Laborer | E52: Telephone # | F52: Type of Improvement Furnished | G52: Total Contract Price | H52: Adjustment to Contract Amount ( +/ -) | I52: Adjusted Contract Price | J52: Amount Already Paid | K52: Current Request | L52: Balance to Complete
A53: 31 | F53: GARAGE DOOR | G53: 0 | H53: 0 | I53: =+G53+H53 -> 0 | L53: =+I53-J53-K53 -> 0
A54: 32 | F54: FINAL GRADING | G54: 0 | H54: 0 | I54: =+G54+H54 -> 0 | L54: =+I54-J54-K54 -> 0
A55: 33 | F55: ELECTRICAL FIXTURES | G55: 0 | H55: 0 | I55: =+G55+H55 -> 0 | L55: =+I55-J55-K55 -> 0
A56: 34 | F56: CARPETING | G56: 0 | H56: 0 | I56: =+G56+H56 -> 0 | L56: =+I56-J56-K56 -> 0
A57: 35 | F57: FLOOR COVERING | G57: 0 | H57: 0 | I57: =+G57+H57 -> 0 | L57: =+I57-J57-K57 -> 0
A58: 36 | F58: BUILT IN APPLIANCES | G58: 0 | H58: 0 | I58: =+G58+H58 -> 0 | L58: =+I58-J58-K58 -> 0
A59: 37 | F59: WELL | G59: 0 | H59: 0 | I59: =+G59+H59 -> 0 | L59: =+I59-J59-K59 -> 0
A60: 38 | F60: SEPTIC | G60: 0 | H60: 0 | I60: =+G60+H60 -> 0 | L60: =+I60-J60-K60 -> 0
A61: 39 | F61: FIREPLACE | G61: 0 | H61: 0 | I61: =+G61+H61 -> 0 | L61: =+I61-J61-K61 -> 0
A62: 40 | F62: DRIVEWAY PAVING | G62: 0 | H62: 0 | I62: =+G62+H62 -> 0 | L62: =+I62-J62-K62 -> 0
A63: 41 | F63: PERMITS | G63: 0 | H63: 0 | I63: =+G63+H63 -> 0 | L63: =+I63-J63-K63 -> 0
A64: 42 | F64: PAYOFFS | G64: 0 | H64: 0 | I64: =+G64+H64 -> 0 | L64: =+I64-J64-K64 -> 0
...

Sheet How to Use Sworn Stmt
A1: How to use this Sworn Statement Template
A3: NOTE: Microsoft Excel is required to use this Sworn Statement.
A5: Entering Information:
A6: 1. Many tabs (worksheets) are located on the bottom of the file:
A7: - Example of Residential Sworn Statement
A8: - How to Use Sworn Statement template
A9: - Master Sworn Statement
A10: - Draw 1
A11: - Draw 2
A13: - Draw 16
A14: - Partial Waiver
A15: - Full Waiver
... A19: Key to navigate through the document. Enter the following:
A20: a. | B20: Owner Name
A21: b. | B21: Contractor Information
A22: i. Company Name
A23: ii. Name of Person submitting sworn statement
A24: iii. Phone #
A25: iv. Email address
A26: v. Cell phone #
A27: c. | B27: Address of the property where construction will take place
A28: d. | B28: County where sworn statement will be Notarized
A29: e. | B29: County Property located in
A30: f. | B30: Names of all Subcontractor, Supplier, or Laborer
A31: g. | B31: Addresses of all Subcontractor, Supplier, or Laborer
A32: h. | B32: Telephone numbers of all Subcontractor, Supplier, or Laborer
A33: i. Company Name | B33: Total Contract Price – should not be changed once initial statement has been submitted
A34: j. | B34: Adjustments – the amount of any change to the initial contract price should be entered in this
B35: column. For increases to the contract price, enter the additional amount. For decreases,
B36: enter (-) and the amount (i.e. -200 to subtract $200 from initial contract amount)
A37: k. | B37: Amount Already Paid – Enter the amounts already paid by the owner prior to first draw
A38: l. | B38: Current Request Column is not available on the Initial Sworn Statement – Amounts requested
B39: must be entered on the specific draw tabs
A41: 3. For each draw requested, Click on the corresponding Draw tab based on the Draw #:
A42: a. | B42: Total Contract Price – is not to be changed once initial statement has been submitted
A43: b. | B43: Adjustments – the amount of any change to the initial contract price is added or subtracted
A44: on the Draw tab. The Adjusted Contract Price column will increase or decrease by the Additional line items (added after initial statement has been submitted) must be | B44: on the Draw tab. The Adjusted Contract Price column will increase or decrease by the
B45: amount input in the Adjustments column. Please offset any adjustment amount with an
B46: adjustment to the Contingency line item in order to keep the net sum of the Adjustments
B47: column at $0.
...

Sheet Master
A1: OWNER'S SWORN STATEMENT
K2: Title Company File #
B3: Owner: | C3: Wolven Investments LLC | F3: General Contractor Name: | G3: Wolven Investments LLC | K3: Phone #
B4: Address of | F4: Person Submitting: | G4: Jeff Klaasen | K4: Email address
B5: Improvements: | C5: 43 North Phase 2 | G5: (authorized person signing sworn statement) | K5: Cell phone #
B7: State of Michigan | D7: ) | G7: (2) The following is a statement of each subcontractor and supplier, and laborer for whom payment of wages or fringe benefits and withholdings is due but unpaid, with whom the (contractor) (subcontractor) has (contracted) (subcontracted) for performance under the contract with the owner or lessee of the property, and the amounts due to the persons as of the date of this statement are correctly and fully set forth opposite their names. (3) The contractor has not procured material from, or subcontracted with, any person other than those set forth and owes no money for the improvement other than the sums set forth. (4) I make this statement as the (contractor) (subcontractor) or as ____________________ of the (contractor) (subcontractor) to represent to the owner or lessee of the property and his or her agents that the property is free from claims of construction liens, or the possibility of construction liens, except as specifically set forth in this statement except for claims of construction liens by laborers that may be provided under Section 109 of the Construction Lien Act, 1980 PA 497, MCL 570.1109.
D8: ) ss.
B9: County of: | C9: Kent | D9: )
B11: =+G4 -> Jeff Klaasen | D11: (deponent), being sworn, states the following:
A12: (1) | B12: Wolven Investmens LLC | D12: is the (contractor) (subcontractor) for an improvement to the following real
B13: property in | C13: =+C9 -> Kent | D13: County, Michigan described as follows:
B16: Name of Subcontractor, Supplier or Laborer | D16: Address of Subcontractor, Supplier or Laborer | E16: Telephone # | F16: Type of Improvement Furnished | G16: Total Contract Price | H16: Adjustment to Contract Amount ( +/ -) | I16: Adjusted Contract Price | J16: Amount Already Paid | K16: Current Request | L16: Balance to Complete
A17: 1 | B17: Jack Dykstra Excavating | D17: 3677 3 Mile Rd., Grand Rapids, MI 49534 | E17: 616-453-4827 | F17: GC Contract Amount | G17: 623097.95 | H17: 0 | I17: =+G17+H17 -> 623097.95 | J17: 138897.29 | L17: =+I17-J17-K17 -> 484200.66
A18: 2 | G18: 0 | H18: 0 | I18: =+G18+H18 -> 0 | J18: 0 | L18: =+I18-J18-K18 -> 0
A19: 3 | B19: Roosien & Associaties | D19: 5055 Plainfield Ave., Grand Rapids, MI 49525 | E19: 616-361-7220 | F19: Engineering Services | G19: 62376 | H19: 0 | I19: =+G19+H19 -> 62376 | J19: 62376 | L19: =+I19-J19-K19 -> 0
A20: 4 | B20: Soils and Structures | D20: 6480 Grand Haven Rd Muskegon MI 49441 | E20: 1-800-933-3959 | F20: Engineering Services | G20: 15930 | H20: 0 | I20: =+G20+H20 -> 15930 | J20: 0 | L20: =+I20-J20-K20 -> 15930
A21: 5 | F21: Engineering Services | G21: =84118.22-62376 -> 21742.22 | H21: 0 | I21: =+G21+H21 -> 21742.22 | L21: =+I21-J21-K21 -> 21742.22
A22: 6 | H22: 0 | I22: =+G22+H22 -> 0 | L22: =+I22-J22-K22 -> 0
A23: 7 | B23: Handicap Sign | D23: 1142 Wealthy St., Grand Rapids, MI 49506 | E23: 616-454-9416 | F23: Common Area Improvements | G23: 424.4 | H23: 0 | I23: =+G23+H23 -> 424.4 | J23: 424.4 | L23: =+I23-J23-K23 -> 0
A24: 8 | B24: Rosendall Well Drilling | D24: 4181 Knapp, Grand Rapids, MI 49525 | E24: 616-363-2683 | F24: Common Area Improvements | G24: 47734 | H24: 0 | I24: =+G24+H24 -> 47734 | J24: 47734 | L24: =+I24-J24-K24 -> 0
A25: 9 | F25: Common Area Improvements | G25: =56373-424.4-47734 -> 8214.6 | H25: 0 | I25: =+G25+H25 -> 8214.6 | L25: =+I25-J25-K25 -> 8214.6
A26: 10 | H26: 0 | I26: =+G26+H26 -> 0 | L26: =+I26-J26-K26 -> 0
A27: 11 | H27: 0 | I27: =+G27+H27 -> 0 | L27: =+I27-J27-K27 -> 0
A28: 12 | H28: 0 | I28: =+G28+H28 -> 0 | L28: =+I28-J28-K28 -> 0
A29: 13 | B29: State of Michigan | D29: Lansing, MI 48909 | F29: Permits and Fees | G29: 800 | H29: 0 | I29: =+G29+H29 -> 800 | J29: 800 | L29: =+I29-J29-K29 -> 0
A30: 14 | B30: Kent County Health Department | D30: 700 Fuller Ave., Grand Rapids, MI 49503 | E30: 616-632-7100 | F30: Permits and Fees | G30: 2635 | H30: 0 | I30: =+G30+H30 -> 2635 | J30: 2635 | L30: =+I30-J30-K30 -> 0
A31: 15 | B31: Kent County Road Commission | D31: 1500 Scribner, Grand Rapids, MI 49504 | E31: 616-242-6900 | F31: Permits and Fees | G31: 13445 | H31: 0 | I31: =+G31+H31 -> 13445 | J31: 13445 | L31: =+I31-J31-K31 -> 0
A32: 16 | B32: Kent County Drain Commission | D32: 1500 Scribner, Grand Rapids, MI 49504 | E32: 616-632-7910 | F32: Permits and Fees | H32: 0 | I32: =+G32+H32 -> 0 | L32: =+I32-J32-K32 -> 0
A33: 17 | B33: Algoma Township | D33: 10531 Algoma Ave., Rockford, MI 49341 | E33: 616-866-1583 | F33: Permits and Fees | G33: =6939+11856 -> 18795 | H33: 0 | I33: =+G33+H33 -> 18795 | J33: =11856+6939 -> 18795 | L33: =+I33-J33-K33 -> 0
A34: 18 | F34: Permits and Fees | G34: =68540.77-15930+1650-800-2635-13445-18795 -> 18585.77 | H34: 0 | I34: =+G34+H34 -> 18585.77 | J34: 0 | L34: =+I34-J34-K34 -> 18585.77
A35: 19 | F35: Electric, Gas, Street Lights | G35: =85320-68518 -> 16802 | H35: 0 | I35: =+G35+H35 -> 16802 | J35: 0 | L35: =+I35-J35-K35 -> 16802
A36: 20 | B36: Consumers Energy | D36: 530 W Willow St. Lansing MI 48909 | E36: 616-530-4210 | F36: Electric, Gas, Street Lights | G36: 68518 | H36: 0 | I36: =+G36+H36 -> 68518 | J36: 0 | L36: =+I36-J36-K36 -> 68518
A37: 21 | B37: DTE Energy | D37: 4420 44th St., Grand Rapids, MI 49512 | E37: 616-278-4720 | F37: Electric, Gas, Street Lights | G37: 0 | H37: 0 | I37: =+G37+H37 -> 0 | J37: 0 | L37: =+I37-J37-K37 -> 0
A38: 22 | F38: Professional Services | G38: =20000-14832.5 -> 5167.5 | H38: 0 | I38: =+G38+H38 -> 5167.5 | L38: =+I38-J38-K38 -> 5167.5
A39: 23 | B39: Rhodes Mckee | D39: 55 Campau Ave. Grand Rapids MI 49503 | E39: 616-235-3500 | F39: Professional Services | G39: 14832.5 | H39: 0 | I39: =+G39+H39 -> 14832.5 | J39: 14832.5 | L39: =+I39-J39-K39 -> 0
A40: 24 | H40: 0 | I40: =+G40+H40 -> 0 | L40: =+I40-J40-K40 -> 0
A41: 25 | I41: =+G41+H41 -> 0 | J41: 0 | L41: =+I41-J41-K41 -> 0
A42: 26 | I42: =+G42+H42 -> 0 | J42: 0 | L42: =+I42-J42-K42 -> 0
A43: 27 | I43: =+G43+H43 -> 0 | L43: =+I43-J43-K43 -> 0
A44: 28 | F44: Contingency | G44: 48532.35 | H44: 0 | I44: =+G44+H44 -> 48532.35 | L44: =+I44-J44-K44 -> 48532.35
...

Sheet Draw 1
A1: OWNER'S SWORN STATEMENT - Draw #1
K2: Title Company File # | L2: =+Master!L2 -> 0
B3: Owner: | C3: =+Master!C3 -> Wolven Investments LLC | F3: General Contractor Name: | G3: =+Master!G3 -> Wolven Investments LLC | K3: Phone # | L3: =+Master!L3 -> 0
B4: Address of | F4: Person Submitting: | G4: =+Master!G4 -> Jeff Klaasen | K4: Email address | L4: =+Master!L4 -> 0
B5: Improvements: | C5: =+Master!C5 -> 43 North Phase 2 | G5: (authorized person signing sworn statement) | K5: Cell phone # | L5: =+Master!L5 -> 0
B7: State of Michigan | D7: ) | G7: (2) The following is a statement of each subcontractor and supplier, and laborer for whom payment of wages or fringe benefits and withholdings is due but unpaid, with whom the (contractor) (subcontractor) has (contracted) (subcontracted) for performance under the contract with the owner or lessee of the property, and the amounts due to the persons as of the date of this statement are correctly and fully set forth opposite their names. (3) The contractor has not procured material from, or subcontracted with, any person other than those set forth and owes no money for the improvement other than the sums set forth. (4) I make this statement as the (contractor) (subcontractor) or as ____________________ of the (contractor) (subcontractor) to represent to the owner or lessee of the property and his or her agents that the property is free from claims of construction liens, or the possibility of construction liens, except as specifically set forth in this statement except for claims of construction liens by laborers that may be provided under Section 109 of the Construction Lien Act, 1980 PA 497, MCL 570.1109.
D8: ) ss.
B9: County of: | C9: =+Master!C9 -> Kent | D9: )
B11: =IF(G4=0,"",G4) -> Jeff Klaasen | D11: (deponent), being sworn, states the following:
A12: (1) | B12: =+G3 -> Wolven Investments LLC | D12: is the (contractor) (subcontractor) for an improvement to the following real
B13: property in | C13: =+C9 -> Kent | D13: County, Michigan described as follows:
B16: Name of Subcontractor, Supplier or Laborer | D16: Address of Subcontractor, Supplier or Laborer | E16: Telephone # | F16: Type of Improvement Furnished | G16: Total Contract Price | H16: Adjustment to Contract Amount ( +/ -) | I16: Adjusted Contract Price | J16: Amount Already Paid | K16: Current Request | L16: Balance to Complete
A17: 1 | B17: =IF(Master!$B17=0,"",Master!$B17) -> Jack Dykstra Excavating | D17: =IF(Master!$D17=0,"",Master!$D17) -> 3677 3 Mile Rd., Grand Rapids, MI 49534 | E17: =IF(Master!$E17=0,"",Master!$E17) -> 616-453-4827 | F17: =IF(Master!$F17=0,"",Master!$F17) -> GC Contract Amount | G17: =Master!G17 -> 623097.95 | H17: =Master!H17 -> 0 | I17: =+G17+H17 -> 623097.95 | J17: =Master!J17 -> 138897.29 | K17: 9246 | L17: =+I17-J17-K17 -> 474954.66
A18: 2 | B18: =IF(Master!$B18=0,"",Master!$B18) | D18: =IF(Master!$D18=0,"",Master!$D18) | E18: =IF(Master!$E18=0,"",Master!$E18) | F18: =IF(Master!$F18=0,"",Master!$F18) | G18: =Master!G18 -> 0 | H18: =Master!H18 -> 0 | I18: =+G18+H18 -> 0 | J18: =Master!J18 -> 0 | L18: =+I18-J18-K18 -> 0
A19: 3 | B19: =IF(Master!$B19=0,"",Master!$B19) -> Roosien & Associaties | D19: =IF(Master!$D19=0,"",Master!$D19) -> 5055 Plainfield Ave., Grand Rapids, MI 49525 | E19: =IF(Master!$E19=0,"",Master!$E19) -> 616-361-7220 | F19: =IF(Master!$F19=0,"",Master!$F19) -> Engineering Services | G19: =Master!G19 -> 62376 | H19: =Master!H19 -> 0 | I19: =+G19+H19 -> 62376 | J19: =Master!J19 -> 62376 | L19: =+I19-J19-K19 -> 0
A20: 4 | B20: =IF(Master!$B20=0,"",Master!$B20) -> Soils and Structures | D20: =IF(Master!$D20=0,"",Master!$D20) -> 6480 Grand Haven Rd Muskegon MI 49441 | E20: =IF(Master!$E20=0,"",Master!$E20) -> 1-800-933-3959 | F20: =IF(Master!$F20=0,"",Master!$F20) -> Engineering Services | G20: =Master!G20 -> 15930 | H20: =Master!H20 -> 0 | I20: =+G20+H20 -> 15930 | J20: =Master!J20 -> 0 | L20: =+I20-J20-K20 -> 15930
A21: 5 | B21: =IF(Master!$B21=0,"",Master!$B21) | D21: =IF(Master!$D21=0,"",Master!$D21) | E21: =IF(Master!$E21=0,"",Master!$E21) | F21: =IF(Master!$F21=0,"",Master!$F21) -> Engineering Services | G21: =Master!G21 -> 21742.22 | H21: =Master!H21 -> 0 | I21: =+G21+H21 -> 21742.22 | J21: =Master!J21 -> 0 | L21: =+I21-J21-K21 -> 21742.22
A22: 6 | B22: =IF(Master!$B22=0,"",Master!$B22) | D22: =IF(Master!$D22=0,"",Master!$D22) | E22: =IF(Master!$E22=0,"",Master!$E22) | F22: =IF(Master!$F22=0,"",Master!$F22) | G22: =Master!G22 -> 0 | H22: =Master!H22 -> 0 | I22: =+G22+H22 -> 0 | J22: =Master!J22 -> 0 | L22: =+I22-J22-K22 -> 0
A23: 7 | B23: =IF(Master!$B23=0,"",Master!$B23) -> Handicap Sign | D23: =IF(Master!$D23=0,"",Master!$D23) -> 1142 Wealthy St., Grand Rapids, MI 49506 | E23: =IF(Master!$E23=0,"",Master!$E23) -> 616-454-9416 | F23: =IF(Master!$F23=0,"",Master!$F23) -> Common Area Improvements | G23: =Master!G23 -> 424.4 | H23: =Master!H23 -> 0 | I23: =+G23+H23 -> 424.4 | J23: =Master!J23 -> 424.4 | L23: =+I23-J23-K23 -> 0
A24: 8 | B24: =IF(Master!$B24=0,"",Master!$B24) -> Rosendall Well Drilling | D24: =IF(Master!$D24=0,"",Master!$D24) -> 4181 Knapp, Grand Rapids, MI 49525 | E24: =IF(Master!$E24=0,"",Master!$E24) -> 616-363-2683 | F24: =IF(Master!$F24=0,"",Master!$F24) -> Common Area Improvements | G24: =Master!G24 -> 47734 | H24: =Master!H24 -> 0 | I24: =+G24+H24 -> 47734 | J24: =Master!J24 -> 47734 | L24: =+I24-J24-K24 -> 0
A25: 9 | B25: =IF(Master!$B25=0,"",Master!$B25) | D25: =IF(Master!$D25=0,"",Master!$D25) | E25: =IF(Master!$E25=0,"",Master!$E25) | F25: =IF(Master!$F25=0,"",Master!$F25) -> Common Area Improvements | G25: =Master!G25 -> 8214.6 | H25: =Master!H25 -> 0 | I25: =+G25+H25 -> 8214.6 | J25: =Master!J25 -> 0 | L25: =+I25-J25-K25 -> 8214.6
A26: 10 | B26: =IF(Master!$B26=0,"",Master!$B26) | D26: =IF(Master!$D26=0,"",Master!$D26) | E26: =IF(Master!$E26=0,"",Master!$E26) | F26: =IF(Master!$F26=0,"",Master!$F26) | G26: =Master!G26 -> 0 | H26: =Master!H26 -> 0 | I26: =+G26+H26 -> 0 | J26: =Master!J26 -> 0 | L26: =+I26-J26-K26 -> 0
A27: 11 | B27: =IF(Master!$B27=0,"",Master!$B27) | D27: =IF(Master!$D27=0,"",Master!$D27) | E27: =IF(Master!$E27=0,"",Master!$E27) | F27: =IF(Master!$F27=0,"",Master!$F27) | G27: =Master!G27 -> 0 | H27: =Master!H27 -> 0 | I27: =+G27+H27 -> 0 | J27: =Master!J27 -> 0 | L27: =+I27-J27-K27 -> 0
A28: 12 | B28: =IF(Master!$B28=0,"",Master!$B28) | D28: =IF(Master!$D28=0,"",Master!$D28) | E28: =IF(Master!$E28=0,"",Master!$E28) | F28: =IF(Master!$F28=0,"",Master!$F28) | G28: =Master!G28 -> 0 | H28: =Master!H28 -> 0 | I28: =+G28+H28 -> 0 | J28: =Master!J28 -> 0 | L28: =+I28-J28-K28 -> 0
A29: 13 | B29: =IF(Master!$B29=0,"",Master!$B29) -> State of Michigan | D29: =IF(Master!$D29=0,"",Master!$D29) -> Lansing, MI 48909 | E29: =IF(Master!$E29=0,"",Master!$E29) | F29: =IF(Master!$F29=0,"",Master!$F29) -> Permits and Fees | G29: =Master!G29 -> 800 | H29: =Master!H29 -> 0 | I29: =+G29+H29 -> 800 | J29: =Master!J29 -> 800 | L29: =+I29-J29-K29 -> 0
... A35: 19 | B35: =IF(Master!$B35=0,"",Master!$B35) | D35: =IF(Master!$D35=0,"",Master!$D35) | E35: =IF(Master!$E35=0,"",Master!$E35) | F35: =IF(Master!$F35=0,"",Master!$F35) -> Electric, Gas, Street Lights | G35: =Master!G35 -> 16802 | H35: =Master!H35 -> 0 | I35: =+G35+H35 -> 16802 | J35: =Master!J35 -> 0 | L35: =+I35-J35-K35 -> 16802
A36: 20 | B36: =IF(Master!$B36=0,"",Master!$B36) -> Consumers Energy | D36: =IF(Master!$D36=0,"",Master!$D36) -> 530 W Willow St. Lansing MI 48909 | E36: =IF(Master!$E36=0,"",Master!$E36) -> 616-530-4210 | F36: =IF(Master!$F36=0,"",Master!$F36) -> Electric, Gas, Street Lights | G36: =Master!G36 -> 68518 | H36: =Master!H36 -> 0 | I36: =+G36+H36 -> 68518 | J36: =Master!J36 -> 0 | K36: 68518 | L36: =+I36-J36-K36 -> 0
A37: 21 | B37: =IF(Master!$B37=0,"",Master!$B37) -> DTE Energy | D37: =IF(Master!$D37=0,"",Master!$D37) -> 4420 44th St., Grand Rapids, MI 49512 | E37: =IF(Master!$E37=0,"",Master!$E37) -> 616-278-4720 | F37: =IF(Master!$F37=0,"",Master!$F37) -> Electric, Gas, Street Lights | G37: =Master!G37 -> 0 | H37: =Master!H37 -> 0 | I37: =+G37+H37 -> 0 | J37: =Master!J37 -> 0 | L37: =+I37-J37-K37 -> 0
A38: 22 | B38: =IF(Master!$B38=0,"",Master!$B38) | D38: =IF(Master!$D38=0,"",Master!$D38) | E38: =IF(Master!$E38=0,"",Master!$E38) | F38: =IF(Master!$F38=0,"",Master!$F38) -> Professional Services | G38: =Master!G38 -> 5167.5 | H38: =Master!H38 -> 0 | I38: =+G38+H38 -> 5167.5 | J38: =Master!J38 -> 0 | L38: =+I38-J38-K38 -> 5167.5
A39: 23 | B39: =IF(Master!$B39=0,"",Master!$B39) -> Rhodes Mckee | D39: =IF(Master!$D39=0,"",Master!$D39) -> 55 Campau Ave. Grand Rapids MI 49503 | E39: =IF(Master!$E39=0,"",Master!$E39) -> 616-235-3500 | F39: =IF(Master!$F39=0,"",Master!$F39) -> Professional Services | G39: =Master!G39 -> 14832.5 | H39: =Master!H39 -> 0 | I39: =+G39+H39 -> 14832.5 | J39: =Master!J39 -> 14832.5 | L39: =+I39-J39-K39 -> 0
A40: 24 | B40: =IF(Master!$B40=0,"",Master!$B40) | D40: =IF(Master!$D40=0,"",Master!$D40) | E40: =IF(Master!$E40=0,"",Master!$E40) | F40: =IF(Master!$F40=0,"",Master!$F40) | G40: =Master!G40 -> 0 | H40: =Master!H40 -> 0 | I40: =+G40+H40 -> 0 | J40: =Master!J40 -> 0 | L40: =+I40-J40-K40 -> 0
A41: 25 | B41: =IF(Master!$B41=0,"",Master!$B41) | D41: =IF(Master!$D41=0,"",Master!$D41) | E41: =IF(Master!$E41=0,"",Master!$E41) | F41: =IF(Master!$F41=0,"",Master!$F41) | G41: =Master!G41 -> 0 | H41: =Master!H41 -> 0 | I41: =+G41+H41 -> 0 | J41: =Master!J41 -> 0 | L41: =+I41-J41-K41 -> 0
A42: 26 | B42: =IF(Master!$B42=0,"",Master!$B42) | D42: =IF(Master!$D42=0,"",Master!$D42) | E42: =IF(Master!$E42=0,"",Master!$E42) | F42: =IF(Master!$F42=0,"",Master!$F42) | G42: =Master!G42 -> 0 | H42: =Master!H42 -> 0 | I42: =+G42+H42 -> 0 | J42: =Master!J42 -> 0 | L42: =+I42-J42-K42 -> 0
A43: 27 | B43: =IF(Master!$B43=0,"",Master!$B43) | D43: =IF(Master!$D43=0,"",Master!$D43) | E43: =IF(Master!$E43=0,"",Master!$E43) | F43: =IF(Master!$F43=0,"",Master!$F43) | G43: =Master!G43 -> 0 | H43: =Master!H43 -> 0 | I43: =+G43+H43 -> 0 | J43: =Master!J43 -> 0 | L43: =+I43-J43-K43 -> 0
A44: 28 | B44: =IF(Master!$B44=0,"",Master!$B44) | D44: =IF(Master!$D44=0,"",Master!$D44) | E44: =IF(Master!$E44=0,"",Master!$E44) | F44: =IF(Master!$F44=0,"",Master!$F44) -> Contingency | G44: =Master!G44 -> 48532.35 | H44: =Master!H44 -> 0 | I44: =+G44+H44 -> 48532.35 | J44: =Master!J44 -> 0 | L44: =+I44-J44-K44 -> 48532.35
A45: 29 | B45: =IF(Master!$B45=0,"",Master!$B45) | D45: =IF(Master!$D45=0,"",Master!$D45) | E45: =IF(Master!$E45=0,"",Master!$E45) | F45: =IF(Master!$F45=0,"",Master!$F45) -> Interest Carry | G45: =Master!G45 -> 46433.43 | H45: =Master!H45 -> 0 | I45: =+G45+H45 -> 46433.43 | J45: =Master!J45 -> 0 | L45: =+I45-J45-K45 -> 46433.43
A46: 30 | B46: =IF(Master!$B46=0,"",Master!$B46) | D46: =IF(Master!$D46=0,"",Master!$D46) | E46: =IF(Master!$E46=0,"",Master!$E46) | F46: =IF(Master!$F46=0,"",Master!$F46) -> Land | G46: =Master!G46 -> 234300 | H46: =Master!H46 -> 0 | I46: =+G46+H46 -> 234300 | J46: =Master!J46 -> 234300 | L46: =+I46-J46-K46 -> 0
F47: SUBTOTALS | G47: =SUM(G17:G46) -> 1268365.7 | H47: =SUM(H17:H46) -> 0 | I47: =SUM(I17:I46) -> 1268365.7 | J47: =SUM(J17:J46) -> 534239.19 | K47: =SUM(K17:K46) -> 77764 | L47: =SUM(L17:L46) -> 656362.53
B48: WARNING TO OWNER OR LESSEE: An owner or lessee of the property may not rely on this sworn statement to avoid the claim of a subcontractor, supplier, or laborer who has provided a Notice of Furnishing or a laborer who may provide a Notice of Furnishing under Section 109 of the Construction Lien Act, 1980 PA 497, MCL 570.1109, to the designee or to the owner or lessee if the designee is not named or has died.
B52: Name of Subcontractor, Supplier or Laborer | D52: Address of Subcontractor, Supplier or Laborer | E52: Telephone # | F52: Type of Improvement Furnished | G52: Total Contract Price | H52: Adjustment to Contract Amount ( +/ -) | I52: Adjusted Contract Price | J52: Amount Already Paid | K52: Current Request | L52: Balance to Complete
...

Sheet Draw 2
A1: OWNER'S SWORN STATEMENT - Draw #2
K2: Title Company File #
B3: Owner: | C3: =+Master!C3 -> Wolven Investments LLC | F3: General Contractor Name: | G3: =+Master!G3 -> Wolven Investments LLC | K3: Phone # | L3: =+Master!L3 -> 0
B4: Address of | F4: Person Submitting: | G4: =+Master!G4 -> Jeff Klaasen | K4: Email address | L4: =+Master!L4 -> 0
B5: Improvements: | C5: =+Master!C5 -> 43 North Phase 2 | G5: (authorized person signing sworn statement) | K5: Cell phone # | L5: =+Master!L5 -> 0
B7: State of Michigan | D7: ) | G7: (2) The following is a statement of each subcontractor and supplier, and laborer for whom payment of wages or fringe benefits and withholdings is due but unpaid, with whom the (contractor) (subcontractor) has (contracted) (subcontracted) for performance under the contract with the owner or lessee of the property, and the amounts due to the persons as of the date of this statement are correctly and fully set forth opposite their names. (3) The contractor has not procured material from, or subcontracted with, any person other than those set forth and owes no money for the improvement other than the sums set forth. (4) I make this statement as the (contractor) (subcontractor) or as ____________________ of the (contractor) (subcontractor) to represent to the owner or lessee of the property and his or her agents that the property is free from claims of construction liens, or the possibility of construction liens, except as specifically set forth in this statement except for claims of construction liens by laborers that may be provided under Section 109 of the Construction Lien Act, 1980 PA 497, MCL 570.1109.
D8: ) ss.
B9: County of: | C9: =+Master!C9 -> Kent | D9: )
B11: =IF(G4=0,"",G4) -> Jeff Klaasen | D11: (deponent), being sworn, states the following:
A12: (1) | B12: =+G3 -> Wolven Investments LLC | D12: is the (contractor) (subcontractor) for an improvement to the following real
B13: property in | C13: =+C9 -> Kent | D13: County, Michigan described as follows:
B16: Name of Subcontractor, Supplier or Laborer | D16: Address of Subcontractor, Supplier or Laborer | E16: Telephone # | F16: Type of Improvement Furnished | G16: Total Contract Price | H16: Adjustment to Contract Amount ( +/ -) | I16: Adjusted Contract Price | J16: Amount Already Paid | K16: Current Request | L16: Balance to Complete
A17: 1 | B17: =IF(Master!$B17=0,"",Master!$B17) -> Jack Dykstra Excavating | D17: =IF(Master!$D17=0,"",Master!$D17) -> 3677 3 Mile Rd., Grand Rapids, MI 49534 | E17: =IF(Master!$E17=0,"",Master!$E17) -> 616-453-4827 | F17: =IF(Master!$F17=0,"",Master!$F17) -> GC Contract Amount | G17: =Master!G17 -> 623097.95 | H17: 1228.5 | I17: =+G17+H17 -> 624326.45 | J17: ='Draw 1'!J17+'Draw 1'!K17 -> 148143.29 | K17: 276327.66 | L17: =+I17-J17-K17 -> 199855.5
A18: 2 | B18: =IF(Master!$B18=0,"",Master!$B18) | D18: =IF(Master!$D18=0,"",Master!$D18) | E18: =IF(Master!$E18=0,"",Master!$E18) | F18: =IF(Master!$F18=0,"",Master!$F18) | G18: =Master!G18 -> 0 | H18: =+'Draw 1'!H18 -> 0 | I18: =+G18+H18 -> 0 | J18: ='Draw 1'!J18+'Draw 1'!K18 -> 0 | L18: =+I18-J18-K18 -> 0
A19: 3 | B19: =IF(Master!$B19=0,"",Master!$B19) -> Roosien & Associaties | D19: =IF(Master!$D19=0,"",Master!$D19) -> 5055 Plainfield Ave., Grand Rapids, MI 49525 | E19: =IF(Master!$E19=0,"",Master!$E19) -> 616-361-7220 | F19: =IF(Master!$F19=0,"",Master!$F19) -> Engineering Services | G19: =Master!G19 -> 62376 | H19: 8555 | I19: =+G19+H19 -> 70931 | J19: ='Draw 1'!J19+'Draw 1'!K19 -> 62376 | K19: =1220+4980+2355 -> 8555 | L19: =+I19-J19-K19 -> 0
A20: 4 | B20: =IF(Master!$B20=0,"",Master!$B20) -> Soils and Structures | D20: =IF(Master!$D20=0,"",Master!$D20) -> 6480 Grand Haven Rd Muskegon MI 49441 | E20: =IF(Master!$E20=0,"",Master!$E20) -> 1-800-933-3959 | F20: =IF(Master!$F20=0,"",Master!$F20) -> Engineering Services | G20: =Master!G20 -> 15930 | H20: =+'Draw 1'!H20 -> 0 | I20: =+G20+H20 -> 15930 | J20: ='Draw 1'!J20+'Draw 1'!K20 -> 0 | K20: 1158.5 | L20: =+I20-J20-K20 -> 14771.5
A21: 5 | B21: =IF(Master!$B21=0,"",Master!$B21) | D21: =IF(Master!$D21=0,"",Master!$D21) | E21: =IF(Master!$E21=0,"",Master!$E21) | F21: =IF(Master!$F21=0,"",Master!$F21) -> Engineering Services | G21: =Master!G21 -> 21742.22 | H21: =+'Draw 1'!H21-8555 -> -8555 | I21: =+G21+H21 -> 13187.22 | J21: ='Draw 1'!J21+'Draw 1'!K21 -> 0 | L21: =+I21-J21-K21 -> 13187.22
A22: 6 | B22: =IF(Master!$B22=0,"",Master!$B22) | D22: =IF(Master!$D22=0,"",Master!$D22) | E22: =IF(Master!$E22=0,"",Master!$E22) | F22: =IF(Master!$F22=0,"",Master!$F22) | G22: =Master!G22 -> 0 | H22: =+'Draw 1'!H22 -> 0 | I22: =+G22+H22 -> 0 | J22: ='Draw 1'!J22+'Draw 1'!K22 -> 0 | L22: =+I22-J22-K22 -> 0
A23: 7 | B23: =IF(Master!$B23=0,"",Master!$B23) -> Handicap Sign | D23: =IF(Master!$D23=0,"",Master!$D23) -> 1142 Wealthy St., Grand Rapids, MI 49506 | E23: =IF(Master!$E23=0,"",Master!$E23) -> 616-454-9416 | F23: =IF(Master!$F23=0,"",Master!$F23) -> Common Area Improvements | G23: =Master!G23 -> 424.4 | H23: =+'Draw 1'!H23 -> 0 | I23: =+G23+H23 -> 424.4 | J23: ='Draw 1'!J23+'Draw 1'!K23 -> 424.4 | L23: =+I23-J23-K23 -> 0
A24: 8 | B24: =IF(Master!$B24=0,"",Master!$B24) -> Rosendall Well Drilling | D24: =IF(Master!$D24=0,"",Master!$D24) -> 4181 Knapp, Grand Rapids, MI 49525 | E24: =IF(Master!$E24=0,"",Master!$E24) -> 616-363-2683 | F24: =IF(Master!$F24=0,"",Master!$F24) -> Common Area Improvements | G24: =Master!G24 -> 47734 | H24: =+'Draw 1'!H24 -> 0 | I24: =+G24+H24 -> 47734 | J24: ='Draw 1'!J24+'Draw 1'!K24 -> 47734 | L24: =+I24-J24-K24 -> 0
A25: 9 | B25: =IF(Master!$B25=0,"",Master!$B25) | D25: =IF(Master!$D25=0,"",Master!$D25) | E25: =IF(Master!$E25=0,"",Master!$E25) | F25: =IF(Master!$F25=0,"",Master!$F25) -> Common Area Improvements | G25: =Master!G25 -> 8214.6 | H25: =+'Draw 1'!H25 -> 0 | I25: =+G25+H25 -> 8214.6 | J25: ='Draw 1'!J25+'Draw 1'!K25 -> 0 | L25: =+I25-J25-K25 -> 8214.6
A26: 10 | B26: =IF(Master!$B26=0,"",Master!$B26) | D26: =IF(Master!$D26=0,"",Master!$D26) | E26: =IF(Master!$E26=0,"",Master!$E26) | F26: =IF(Master!$F26=0,"",Master!$F26) | G26: =Master!G26 -> 0 | H26: =+'Draw 1'!H26 -> 0 | I26: =+G26+H26 -> 0 | J26: ='Draw 1'!J26+'Draw 1'!K26 -> 0 | L26: =+I26-J26-K26 -> 0
A27: 11 | B27: =IF(Master!$B27=0,"",Master!$B27) | D27: =IF(Master!$D27=0,"",Master!$D27) | E27: =IF(Master!$E27=0,"",Master!$E27) | F27: =IF(Master!$F27=0,"",Master!$F27) | G27: =Master!G27 -> 0 | H27: =+'Draw 1'!H27 -> 0 | I27: =+G27+H27 -> 0 | J27: ='Draw 1'!J27+'Draw 1'!K27 -> 0 | L27: =+I27-J27-K27 -> 0
A28: 12 | B28: =IF(Master!$B28=0,"",Master!$B28) | D28: =IF(Master!$D28=0,"",Master!$D28) | E28: =IF(Master!$E28=0,"",Master!$E28) | F28: =IF(Master!$F28=0,"",Master!$F28) | G28: =Master!G28 -> 0 | H28: =+'Draw 1'!H28 -> 0 | I28: =+G28+H28 -> 0 | J28: ='Draw 1'!J28+'Draw 1'!K28 -> 0 | L28: =+I28-J28-K28 -> 0
A29: 13 | B29: =IF(Master!$B29=0,"",Master!$B29) -> State of Michigan | D29: =IF(Master!$D29=0,"",Master!$D29) -> Lansing, MI 48909 | E29: =IF(Master!$E29=0,"",Master!$E29) | F29: =IF(Master!$F29=0,"",Master!$F29) -> Permits and Fees | G29: =Master!G29 -> 800 | H29: =+'Draw 1'!H29 -> 0 | I29: =+G29+H29 -> 800 | J29: ='Draw 1'!J29+'Draw 1'!K29 -> 800 | L29: =+I29-J29-K29 -> 0
A30: 14 | B30: =IF(Master!$B30=0,"",Master!$B30) -> Kent County Health Department | D30: =IF(Master!$D30=0,"",Master!$D30) -> 700 Fuller Ave., Grand Rapids, MI 49503 | E30: =IF(Master!$E30=0,"",Master!$E30) -> 616-632-7100 | F30: =IF(Master!$F30=0,"",Master!$F30) -> Permits and Fees | G30: =Master!G30 -> 2635 | H30: =+'Draw 1'!H30 -> 0 | I30: =+G30+H30 -> 2635 | J30: ='Draw 1'!J30+'Draw 1'!K30 -> 2635 | L30: =+I30-J30-K30 -> 0
A31: 15 | B31: =IF(Master!$B31=0,"",Master!$B31) -> Kent County Road Commission | D31: =IF(Master!$D31=0,"",Master!$D31) -> 1500 Scribner, Grand Rapids, MI 49504 | E31: =IF(Master!$E31=0,"",Master!$E31) -> 616-242-6900 | F31: =IF(Master!$F31=0,"",Master!$F31) -> Permits and Fees | G31: =Master!G31 -> 13445 | H31: =+'Draw 1'!H31 -> 0 | I31: =+G31+H31 -> 13445 | J31: ='Draw 1'!J31+'Draw 1'!K31 -> 13445 | L31: =+I31-J31-K31 -> 0
A32: 16 | B32: =IF(Master!$B32=0,"",Master!$B32) -> Kent County Drain Commission | D32: =IF(Master!$D32=0,"",Master!$D32) -> 1500 Scribner, Grand Rapids, MI 49504 | E32: =IF(Master!$E32=0,"",Master!$E32) -> 616-632-7910 | F32: =IF(Master!$F32=0,"",Master!$F32) -> Permits and Fees | G32: =Master!G32 -> 0 | H32: =+'Draw 1'!H32 -> 0 | I32: =+G32+H32 -> 0 | J32: ='Draw 1'!J32+'Draw 1'!K32 -> 0 | L32: =+I32-J32-K32 -> 0
A33: 17 | B33: =IF(Master!$B33=0,"",Master!$B33) -> Algoma Township | D33: =IF(Master!$D33=0,"",Master!$D33) -> 10531 Algoma Ave., Rockford, MI 49341 | E33: =IF(Master!$E33=0,"",Master!$E33) -> 616-866-1583 | F33: =IF(Master!$F33=0,"",Master!$F33) -> Permits and Fees | G33: =Master!G33 -> 18795 | H33: =+'Draw 1'!H33 -> 0 | I33: =+G33+H33 -> 18795 | J33: ='Draw 1'!J33+'Draw 1'!K33 -> 18795 | L33: =+I33-J33-K33 -> 0
... A43: 27 | B43: =IF(Master!$B43=0,"",Master!$B43) | D43: =IF(Master!$D43=0,"",Master!$D43) | E43: =IF(Master!$E43=0,"",Master!$E43) | F43: =IF(Master!$F43=0,"",Master!$F43) | G43: =Master!G43 -> 0 | H43: =+'Draw 1'!H43 -> 0 | I43: =+G43+H43 -> 0 | J43: ='Draw 1'!J43+'Draw 1'!K43 -> 0 | L43: =+I43-J43-K43 -> 0
A44: 28 | B44: =IF(Master!$B44=0,"",Master!$B44) | D44: =IF(Master!$D44=0,"",Master!$D44) | E44: =IF(Master!$E44=0,"",Master!$E44) | F44: =IF(Master!$F44=0,"",Master!$F44) -> Contingency | G44: =Master!G44 -> 48532.35 | H44: -1228.5 | I44: =+G44+H44 -> 47303.85 | J44: ='Draw 1'!J44+'Draw 1'!K44 -> 0 | L44: =+I44-J44-K44 -> 47303.85
A45: 29 | B45: =IF(Master!$B45=0,"",Master!$B45) | D45: =IF(Master!$D45=0,"",Master!$D45) | E45: =IF(Master!$E45=0,"",Master!$E45) | F45: =IF(Master!$F45=0,"",Master!$F45) -> Interest Carry | G45: =Master!G45 -> 46433.43 | H45: =+'Draw 1'!H45 -> 0 | I45: =+G45+H45 -> 46433.43 | J45: ='Draw 1'!J45+'Draw 1'!K45 -> 0 | L45: =+I45-J45-K45 -> 46433.43
A46: 30 | B46: =IF(Master!$B46=0,"",Master!$B46) | D46: =IF(Master!$D46=0,"",Master!$D46) | E46: =IF(Master!$E46=0,"",Master!$E46) | F46: =IF(Master!$F46=0,"",Master!$F46) -> Land | G46: =Master!G46 -> 234300 | H46: =+'Draw 1'!H46 -> 0 | I46: =+G46+H46 -> 234300 | J46: ='Draw 1'!J46+'Draw 1'!K46 -> 234300 | L46: =+I46-J46-K46 -> 0
F47: SUBTOTALS | G47: =SUM(G17:G46) -> 1268365.7 | H47: =SUM(H17:H46) -> 0 | I47: =SUM(I17:I46) -> 1268365.7 | J47: =SUM(J17:J46) -> 612003.19 | K47: =SUM(K17:K46) -> 286041.16 | L47: =SUM(L17:L46) -> 370321.37
B48: WARNING TO OWNER OR LESSEE: An owner or lessee of the property may not rely on this sworn statement to avoid the claim of a subcontractor, supplier, or laborer who has provided a Notice of Furnishing or a laborer who may provide a Notice of Furnishing under Section 109 of the Construction Lien Act, 1980 PA 497, MCL 570.1109, to the designee or to the owner or lessee if the designee is not named or has died.
B52: Name of Subcontractor, Supplier or Laborer | D52: Address of Subcontractor, Supplier or Laborer | E52: Telephone # | F52: Type of Improvement Furnished | G52: Total Contract Price | H52: Adjustment to Contract Amount ( +/ -) | I52: Adjusted Contract Price | J52: Amount Already Paid | K52: Current Request | L52: Balance to Complete
A53: 31 | B53: =IF(Master!$B53=0,"",Master!$B53) | D53: =IF(Master!$D53=0,"",Master!$D53) | E53: =IF(Master!$E53=0,"",Master!$E53) | F53: =IF(Master!$F53=0,"",Master!$F53) | G53: =Master!G53 -> 0 | H53: =+'Draw 1'!H53 -> 0 | I53: =+G53+H53 -> 0 | J53: ='Draw 1'!J53+'Draw 1'!K53 -> 0 | L53: =+I53-J53-K53 -> 0
A54: 32 | B54: =IF(Master!$B54=0,"",Master!$B54) | D54: =IF(Master!$D54=0,"",Master!$D54) | E54: =IF(Master!$E54=0,"",Master!$E54) | F54: =IF(Master!$F54=0,"",Master!$F54) | G54: =Master!G54 -> 0 | H54: =+'Draw 1'!H54 -> 0 | I54: =+G54+H54 -> 0 | J54: ='Draw 1'!J54+'Draw 1'!K54 -> 0 | L54: =+I54-J54-K54 -> 0
A55: 33 | B55: =IF(Master!$B55=0,"",Master!$B55) | D55: =IF(Master!$D55=0,"",Master!$D55) | E55: =IF(Master!$E55=0,"",Master!$E55) | F55: =IF(Master!$F55=0,"",Master!$F55) | G55: =Master!G55 -> 0 | H55: =+'Draw 1'!H55 -> 0 | I55: =+G55+H55 -> 0 | J55: ='Draw 1'!J55+'Draw 1'!K55 -> 0 | L55: =+I55-J55-K55 -> 0
A56: 34 | B56: =IF(Master!$B56=0,"",Master!$B56) | D56: =IF(Master!$D56=0,"",Master!$D56) | E56: =IF(Master!$E56=0,"",Master!$E56) | F56: =IF(Master!$F56=0,"",Master!$F56) | G56: =Master!G56 -> 0 | H56: =+'Draw 1'!H56 -> 0 | I56: =+G56+H56 -> 0 | J56: ='Draw 1'!J56+'Draw 1'!K56 -> 0 | L56: =+I56-J56-K56 -> 0
...

Sheet Draw 3
A1: OWNER'S SWORN STATEMENT - Draw #3
K2: Title Company File #
B3: Owner: | C3: =+Master!C3 -> Wolven Investments LLC | F3: General Contractor Name: | G3: =+Master!G3 -> Wolven Investments LLC | K3: Phone # | L3: =+Master!L3 -> 0
B4: Address of | F4: Person Submitting: | G4: =+Master!G4 -> Jeff Klaasen | K4: Email address | L4: =+Master!L4 -> 0
B5: Improvements: | C5: =+Master!C5 -> 43 North Phase 2 | G5: (authorized person signing sworn statement) | K5: Cell phone # | L5: =+Master!L5 -> 0
B7: State of Michigan | D7: ) | G7: (2) The following is a statement of each subcontractor and supplier, and laborer for whom payment of wages or fringe benefits and withholdings is due but unpaid, with whom the (contractor) (subcontractor) has (contracted) (subcontracted) for performance under the contract with the owner or lessee of the property, and the amounts due to the persons as of the date of this statement are correctly and fully set forth opposite their names. (3) The contractor has not procured material from, or subcontracted with, any person other than those set forth and owes no money for the improvement other than the sums set forth. (4) I make this statement as the (contractor) (subcontractor) or as ____________________ of the (contractor) (subcontractor) to represent to the owner or lessee of the property and his or her agents that the property is free from claims of construction liens, or the possibility of construction liens, except as specifically set forth in this statement except for claims of construction liens by laborers that may be provided under Section 109 of the Construction Lien Act, 1980 PA 497, MCL 570.1109.
D8: ) ss.
B9: County of: | C9: =+Master!C9 -> Kent | D9: )
B11: =IF(G4=0,"",G4) -> Jeff Klaasen | D11: (deponent), being sworn, states the following:
A12: (1) | B12: =+G3 -> Wolven Investments LLC | D12: is the (contractor) (subcontractor) for an improvement to the following real
B13: property in | C13: =+C9 -> Kent | D13: County, Michigan described as follows:
B16: Name of Subcontractor, Supplier or Laborer | D16: Address of Subcontractor, Supplier or Laborer | E16: Telephone # | F16: Type of Improvement Furnished | G16: Total Contract Price | H16: Adjustment to Contract Amount ( +/ -) | I16: Adjusted Contract Price | J16: Amount Already Paid | K16: Current Request | L16: Balance to Complete
A17: 1 | B17: =IF(Master!$B17=0,"",Master!$B17) -> Jack Dykstra Excavating | D17: =IF(Master!$D17=0,"",Master!$D17) -> 3677 3 Mile Rd., Grand Rapids, MI 49534 | E17: =IF(Master!$E17=0,"",Master!$E17) -> 616-453-4827 | F17: =IF(Master!$F17=0,"",Master!$F17) -> GC Contract Amount | G17: =Master!G17 -> 623097.95 | H17: =+'Draw 2'!H17+17306.75 -> 18535.25 | I17: =+G17+H17 -> 641633.2 | J17: ='Draw 2'!J17+'Draw 2'!K17 -> 424470.95 | K17: 127875.25 | L17: =+I17-J17-K17 -> 89287
A18: 2 | B18: =IF(Master!$B18=0,"",Master!$B18) | D18: =IF(Master!$D18=0,"",Master!$D18) | E18: =IF(Master!$E18=0,"",Master!$E18) | F18: =IF(Master!$F18=0,"",Master!$F18) | G18: =Master!G18 -> 0 | H18: =+'Draw 2'!H18 -> 0 | I18: =+G18+H18 -> 0 | J18: ='Draw 2'!J18+'Draw 2'!K18 -> 0 | L18: =+I18-J18-K18 -> 0
A19: 3 | B19: =IF(Master!$B19=0,"",Master!$B19) -> Roosien & Associaties | D19: =IF(Master!$D19=0,"",Master!$D19) -> 5055 Plainfield Ave., Grand Rapids, MI 49525 | E19: =IF(Master!$E19=0,"",Master!$E19) -> 616-361-7220 | F19: =IF(Master!$F19=0,"",Master!$F19) -> Engineering Services | G19: =Master!G19 -> 62376 | H19: =+'Draw 2'!H19+3240 -> 11795 | I19: =+G19+H19 -> 74171 | J19: ='Draw 2'!J19+'Draw 2'!K19 -> 70931 | K19: 3240 | L19: =+I19-J19-K19 -> 0
A20: 4 | B20: =IF(Master!$B20=0,"",Master!$B20) -> Soils and Structures | D20: =IF(Master!$D20=0,"",Master!$D20) -> 6480 Grand Haven Rd Muskegon MI 49441 | E20: =IF(Master!$E20=0,"",Master!$E20) -> 1-800-933-3959 | F20: =IF(Master!$F20=0,"",Master!$F20) -> Engineering Services | G20: =Master!G20 -> 15930 | H20: =+'Draw 2'!H20 -> 0 | I20: =+G20+H20 -> 15930 | J20: ='Draw 2'!J20+'Draw 2'!K20 -> 1158.5 | K20: 924 | L20: =+I20-J20-K20 -> 13847.5
A21: 5 | B21: =IF(Master!$B21=0,"",Master!$B21) | D21: =IF(Master!$D21=0,"",Master!$D21) | E21: =IF(Master!$E21=0,"",Master!$E21) | F21: =IF(Master!$F21=0,"",Master!$F21) -> Engineering Services | G21: =Master!G21 -> 21742.22 | H21: =+'Draw 2'!H21-3240 -> -11795 | I21: =+G21+H21 -> 9947.22 | J21: ='Draw 2'!J21+'Draw 2'!K21 -> 0 | L21: =+I21-J21-K21 -> 9947.22
A22: 6 | B22: =IF(Master!$B22=0,"",Master!$B22) | D22: =IF(Master!$D22=0,"",Master!$D22) | E22: =IF(Master!$E22=0,"",Master!$E22) | F22: =IF(Master!$F22=0,"",Master!$F22) | G22: =Master!G22 -> 0 | H22: =+'Draw 2'!H22 -> 0 | I22: =+G22+H22 -> 0 | J22: ='Draw 2'!J22+'Draw 2'!K22 -> 0 | L22: =+I22-J22-K22 -> 0
A23: 7 | B23: =IF(Master!$B23=0,"",Master!$B23) -> Handicap Sign | D23: =IF(Master!$D23=0,"",Master!$D23) -> 1142 Wealthy St., Grand Rapids, MI 49506 | E23: =IF(Master!$E23=0,"",Master!$E23) -> 616-454-9416 | F23: =IF(Master!$F23=0,"",Master!$F23) -> Common Area Improvements | G23: =Master!G23 -> 424.4 | H23: =+'Draw 2'!H23 -> 0 | I23: =+G23+H23 -> 424.4 | J23: ='Draw 2'!J23+'Draw 2'!K23 -> 424.4 | L23: =+I23-J23-K23 -> 0
A24: 8 | B24: =IF(Master!$B24=0,"",Master!$B24) -> Rosendall Well Drilling | D24: =IF(Master!$D24=0,"",Master!$D24) -> 4181 Knapp, Grand Rapids, MI 49525 | E24: =IF(Master!$E24=0,"",Master!$E24) -> 616-363-2683 | F24: =IF(Master!$F24=0,"",Master!$F24) -> Common Area Improvements | G24: =Master!G24 -> 47734 | H24: =+'Draw 2'!H24 -> 0 | I24: =+G24+H24 -> 47734 | J24: ='Draw 2'!J24+'Draw 2'!K24 -> 47734 | L24: =+I24-J24-K24 -> 0
A25: 9 | B25: =IF(Master!$B25=0,"",Master!$B25) | D25: =IF(Master!$D25=0,"",Master!$D25) | E25: =IF(Master!$E25=0,"",Master!$E25) | F25: =IF(Master!$F25=0,"",Master!$F25) -> Common Area Improvements | G25: =Master!G25 -> 8214.6 | H25: =+'Draw 2'!H25 -> 0 | I25: =+G25+H25 -> 8214.6 | J25: ='Draw 2'!J25+'Draw 2'!K25 -> 0 | L25: =+I25-J25-K25 -> 8214.6
A26: 10 | B26: =IF(Master!$B26=0,"",Master!$B26) | D26: =IF(Master!$D26=0,"",Master!$D26) | E26: =IF(Master!$E26=0,"",Master!$E26) | F26: =IF(Master!$F26=0,"",Master!$F26) | G26: =Master!G26 -> 0 | H26: =+'Draw 2'!H26 -> 0 | I26: =+G26+H26 -> 0 | J26: ='Draw 2'!J26+'Draw 2'!K26 -> 0 | L26: =+I26-J26-K26 -> 0
A27: 11 | B27: =IF(Master!$B27=0,"",Master!$B27) | D27: =IF(Master!$D27=0,"",Master!$D27) | E27: =IF(Master!$E27=0,"",Master!$E27) | F27: =IF(Master!$F27=0,"",Master!$F27) | G27: =Master!G27 -> 0 | H27: =+'Draw 2'!H27 -> 0 | I27: =+G27+H27 -> 0 | J27: ='Draw 2'!J27+'Draw 2'!K27 -> 0 | L27: =+I27-J27-K27 -> 0
A28: 12 | B28: =IF(Master!$B28=0,"",Master!$B28) | D28: =IF(Master!$D28=0,"",Master!$D28) | E28: =IF(Master!$E28=0,"",Master!$E28) | F28: =IF(Master!$F28=0,"",Master!$F28) | G28: =Master!G28 -> 0 | H28: =+'Draw 2'!H28 -> 0 | I28: =+G28+H28 -> 0 | J28: ='Draw 2'!J28+'Draw 2'!K28 -> 0 | L28: =+I28-J28-K28 -> 0
A29: 13 | B29: =IF(Master!$B29=0,"",Master!$B29) -> State of Michigan | D29: =IF(Master!$D29=0,"",Master!$D29) -> Lansing, MI 48909 | E29: =IF(Master!$E29=0,"",Master!$E29) | F29: =IF(Master!$F29=0,"",Master!$F29) -> Permits and Fees | G29: =Master!G29 -> 800 | H29: =+'Draw 2'!H29 -> 0 | I29: =+G29+H29 -> 800 | J29: ='Draw 2'!J29+'Draw 2'!K29 -> 800 | L29: =+I29-J29-K29 -> 0
A30: 14 | B30: =IF(Master!$B30=0,"",Master!$B30) -> Kent County Health Department | D30: =IF(Master!$D30=0,"",Master!$D30) -> 700 Fuller Ave., Grand Rapids, MI 49503 | E30: =IF(Master!$E30=0,"",Master!$E30) -> 616-632-7100 | F30: =IF(Master!$F30=0,"",Master!$F30) -> Permits and Fees | G30: =Master!G30 -> 2635 | H30: =+'Draw 2'!H30 -> 0 | I30: =+G30+H30 -> 2635 | J30: ='Draw 2'!J30+'Draw 2'!K30 -> 2635 | L30: =+I30-J30-K30 -> 0
A31: 15 | B31: =IF(Master!$B31=0,"",Master!$B31) -> Kent County Road Commission | D31: =IF(Master!$D31=0,"",Master!$D31) -> 1500 Scribner, Grand Rapids, MI 49504 | E31: =IF(Master!$E31=0,"",Master!$E31) -> 616-242-6900 | F31: =IF(Master!$F31=0,"",Master!$F31) -> Permits and Fees | G31: =Master!G31 -> 13445 | H31: 675 | I31: =+G31+H31 -> 14120 | J31: ='Draw 2'!J31+'Draw 2'!K31 -> 13445 | K31: 675 | L31: =+I31-J31-K31 -> 0
A32: 16 | B32: =IF(Master!$B32=0,"",Master!$B32) -> Kent County Drain Commission | D32: =IF(Master!$D32=0,"",Master!$D32) -> 1500 Scribner, Grand Rapids, MI 49504 | E32: =IF(Master!$E32=0,"",Master!$E32) -> 616-632-7910 | F32: =IF(Master!$F32=0,"",Master!$F32) -> Permits and Fees | G32: =Master!G32 -> 0 | H32: =+'Draw 2'!H32 -> 0 | I32: =+G32+H32 -> 0 | J32: ='Draw 2'!J32+'Draw 2'!K32 -> 0 | L32: =+I32-J32-K32 -> 0
A33: 17 | B33: =IF(Master!$B33=0,"",Master!$B33) -> Algoma Township | D33: =IF(Master!$D33=0,"",Master!$D33) -> 10531 Algoma Ave., Rockford, MI 49341 | E33: =IF(Master!$E33=0,"",Master!$E33) -> 616-866-1583 | F33: =IF(Master!$F33=0,"",Master!$F33) -> Permits and Fees | G33: =Master!G33 -> 18795 | H33: =+'Draw 2'!H33 -> 0 | I33: =+G33+H33 -> 18795 | J33: ='Draw 2'!J33+'Draw 2'!K33 -> 18795 | L33: =+I33-J33-K33 -> 0
A34: 18 | B34: =IF(Master!$B34=0,"",Master!$B34) | D34: =IF(Master!$D34=0,"",Master!$D34) | E34: =IF(Master!$E34=0,"",Master!$E34) | F34: =IF(Master!$F34=0,"",Master!$F34) -> Permits and Fees | G34: =Master!G34 -> 18585.77 | H34: -675 | I34: =+G34+H34 -> 17910.77 | J34: ='Draw 2'!J34+'Draw 2'!K34 -> 0 | L34: =+I34-J34-K34 -> 17910.77
A35: 19 | B35: =IF(Master!$B35=0,"",Master!$B35) | D35: =IF(Master!$D35=0,"",Master!$D35) | E35: =IF(Master!$E35=0,"",Master!$E35) | F35: =IF(Master!$F35=0,"",Master!$F35) -> Electric, Gas, Street Lights | G35: =Master!G35 -> 16802 | H35: =+'Draw 2'!H35 -> 0 | I35: =+G35+H35 -> 16802 | J35: ='Draw 2'!J35+'Draw 2'!K35 -> 0 | L35: =+I35-J35-K35 -> 16802
A36: 20 | B36: =IF(Master!$B36=0,"",Master!$B36) -> Consumers Energy | D36: =IF(Master!$D36=0,"",Master!$D36) -> 530 W Willow St. Lansing MI 48909 | E36: =IF(Master!$E36=0,"",Master!$E36) -> 616-530-4210 | F36: =IF(Master!$F36=0,"",Master!$F36) -> Electric, Gas, Street Lights | G36: =Master!G36 -> 68518 | H36: =+'Draw 2'!H36 -> 0 | I36: =+G36+H36 -> 68518 | J36: ='Draw 2'!J36+'Draw 2'!K36 -> 68518 | L36: =+I36-J36-K36 -> 0
A37: 21 | B37: =IF(Master!$B37=0,"",Master!$B37) -> DTE Energy | D37: =IF(Master!$D37=0,"",Master!$D37) -> 4420 44th St., Grand Rapids, MI 49512 | E37: =IF(Master!$E37=0,"",Master!$E37) -> 616-278-4720 | F37: =IF(Master!$F37=0,"",Master!$F37) -> Electric, Gas, Street Lights | G37: =Master!G37 -> 0 | H37: =+'Draw 2'!H37 -> 0 | I37: =+G37+H37 -> 0 | J37: ='Draw 2'!J37+'Draw 2'!K37 -> 0 | L37: =+I37-J37-K37 -> 0
A38: 22 | B38: =IF(Master!$B38=0,"",Master!$B38) | D38: =IF(Master!$D38=0,"",Master!$D38) | E38: =IF(Master!$E38=0,"",Master!$E38) | F38: =IF(Master!$F38=0,"",Master!$F38) -> Professional Services | G38: =Master!G38 -> 5167.5 | H38: -747.5 | I38: =+G38+H38 -> 4420 | J38: ='Draw 2'!J38+'Draw 2'!K38 -> 0 | L38: =+I38-J38-K38 -> 4420
A39: 23 | B39: =IF(Master!$B39=0,"",Master!$B39) -> Rhodes Mckee | D39: =IF(Master!$D39=0,"",Master!$D39) -> 55 Campau Ave. Grand Rapids MI 49503 | E39: =IF(Master!$E39=0,"",Master!$E39) -> 616-235-3500 | F39: =IF(Master!$F39=0,"",Master!$F39) -> Professional Services | G39: =Master!G39 -> 14832.5 | H39: 747.5 | I39: =+G39+H39 -> 15580 | J39: ='Draw 2'!J39+'Draw 2'!K39 -> 14832.5 | K39: 747.5 | L39: =+I39-J39-K39 -> 0
A40: 24 | B40: =IF(Master!$B40=0,"",Master!$B40) | D40: =IF(Master!$D40=0,"",Master!$D40) | E40: =IF(Master!$E40=0,"",Master!$E40) | F40: =IF(Master!$F40=0,"",Master!$F40) | G40: =Master!G40 -> 0 | H40: =+'Draw 2'!H40 -> 0 | I40: =+G40+H40 -> 0 | J40: ='Draw 2'!J40+'Draw 2'!K40 -> 0 | L40: =+I40-J40-K40 -> 0
A41: 25 | B41: =IF(Master!$B41=0,"",Master!$B41) | D41: =IF(Master!$D41=0,"",Master!$D41) | E41: =IF(Master!$E41=0,"",Master!$E41) | F41: =IF(Master!$F41=0,"",Master!$F41) | G41: =Master!G41 -> 0 | H41: =+'Draw 2'!H41 -> 0 | I41: =+G41+H41 -> 0 | J41: ='Draw 2'!J41+'Draw 2'!K41 -> 0 | L41: =+I41-J41-K41 -> 0
A42: 26 | B42: =IF(Master!$B42=0,"",Master!$B42) | D42: =IF(Master!$D42=0,"",Master!$D42) | E42: =IF(Master!$E42=0,"",Master!$E42) | F42: =IF(Master!$F42=0,"",Master!$F42) | G42: =Master!G42 -> 0 | H42: =+'Draw 2'!H42 -> 0 | I42: =+G42+H42 -> 0 | J42: ='Draw 2'!J42+'Draw 2'!K42 -> 0 | L42: =+I42-J42-K42 -> 0
A43: 27 | B43: =IF(Master!$B43=0,"",Master!$B43) | D43: =IF(Master!$D43=0,"",Master!$D43) | E43: =IF(Master!$E43=0,"",Master!$E43) | F43: =IF(Master!$F43=0,"",Master!$F43) | G43: =Master!G43 -> 0 | H43: =+'Draw 2'!H43 -> 0 | I43: =+G43+H43 -> 0 | J43: ='Draw 2'!J43+'Draw 2'!K43 -> 0 | L43: =+I43-J43-K43 -> 0
A44: 28 | B44: =IF(Master!$B44=0,"",Master!$B44) | D44: =IF(Master!$D44=0,"",Master!$D44) | E44: =IF(Master!$E44=0,"",Master!$E44) | F44: =IF(Master!$F44=0,"",Master!$F44) -> Contingency | G44: =Master!G44 -> 48532.35 | H44: =+'Draw 2'!H44-17306.75 -> -18535.25 | I44: =+G44+H44 -> 29997.1 | J44: ='Draw 2'!J44+'Draw 2'!K44 -> 0 | L44: =+I44-J44-K44 -> 29997.1
...

Sheet Draw 4
A1: OWNER'S SWORN STATEMENT - Draw #4
K2: Title Company File #
B3: Owner: | C3: =+Master!C3 -> Wolven Investments LLC | F3: General Contractor Name: | G3: =+Master!G3 -> Wolven Investments LLC | K3: Phone # | L3: =+Master!L3 -> 0
B4: Address of | F4: Person Submitting: | G4: =+Master!G4 -> Jeff Klaasen | K4: Email address | L4: =+Master!L4 -> 0
B5: Improvements: | C5: =+Master!C5 -> 43 North Phase 2 | G5: (authorized person signing sworn statement) | K5: Cell phone # | L5: =+Master!L5 -> 0
B7: State of Michigan | D7: ) | G7: (2) The following is a statement of each subcontractor and supplier, and laborer for whom payment of wages or fringe benefits and withholdings is due but unpaid, with whom the (contractor) (subcontractor) has (contracted) (subcontracted) for performance under the contract with the owner or lessee of the property, and the amounts due to the persons as of the date of this statement are correctly and fully set forth opposite their names. (3) The contractor has not procured material from, or subcontracted with, any person other than those set forth and owes no money for the improvement other than the sums set forth. (4) I make this statement as the (contractor) (subcontractor) or as ____________________ of the (contractor) (subcontractor) to represent to the owner or lessee of the property and his or her agents that the property is free from claims of construction liens, or the possibility of construction liens, except as specifically set forth in this statement except for claims of construction liens by laborers that may be provided under Section 109 of the Construction Lien Act, 1980 PA 497, MCL 570.1109.
D8: ) ss.
B9: County of: | C9: =+Master!C9 -> Kent | D9: )
B11: =IF(G4=0,"",G4) -> Jeff Klaasen | D11: (deponent), being sworn, states the following:
A12: (1) | B12: =+G3 -> Wolven Investments LLC | D12: is the (contractor) (subcontractor) for an improvement to the following real
B13: property in | C13: =+C9 -> Kent | D13: County, Michigan described as follows:
B16: Name of Subcontractor, Supplier or Laborer | D16: Address of Subcontractor, Supplier or Laborer | E16: Telephone # | F16: Type of Improvement Furnished | G16: Total Contract Price | H16: Adjustment to Contract Amount ( +/ -) | I16: Adjusted Contract Price | J16: Amount Already Paid | K16: Current Request | L16: Balance to Complete
A17: 1 | B17: =IF(Master!$B17=0,"",Master!$B17) -> Jack Dykstra Excavating | D17: =IF(Master!$D17=0,"",Master!$D17) -> 3677 3 Mile Rd., Grand Rapids, MI 49534 | E17: =IF(Master!$E17=0,"",Master!$E17) -> 616-453-4827 | F17: =IF(Master!$F17=0,"",Master!$F17) -> GC Contract Amount | G17: =Master!G17 -> 623097.95 | H17: ='Draw 3'!H17 -> 18535.25 | I17: =+G17+H17 -> 641633.2 | J17: ='Draw 3'!J17+'Draw 3'!K17 -> 552346.2 | K17: 89287 | L17: =+I17-J17-K17 -> 0
A18: 2 | B18: =IF(Master!$B18=0,"",Master!$B18) | D18: =IF(Master!$D18=0,"",Master!$D18) | E18: =IF(Master!$E18=0,"",Master!$E18) | F18: =IF(Master!$F18=0,"",Master!$F18) | G18: =Master!G18 -> 0 | H18: ='Draw 3'!H18 -> 0 | I18: =+G18+H18 -> 0 | J18: ='Draw 3'!J18+'Draw 3'!K18 -> 0 | L18: =+I18-J18-K18 -> 0
A19: 3 | B19: =IF(Master!$B19=0,"",Master!$B19) -> Roosien & Associaties | D19: =IF(Master!$D19=0,"",Master!$D19) -> 5055 Plainfield Ave., Grand Rapids, MI 49525 | E19: =IF(Master!$E19=0,"",Master!$E19) -> 616-361-7220 | F19: =IF(Master!$F19=0,"",Master!$F19) -> Engineering Services | G19: =Master!G19 -> 62376 | H19: ='Draw 3'!H19+3355 -> 15150 | I19: =+G19+H19 -> 77526 | J19: ='Draw 3'!J19+'Draw 3'!K19 -> 74171 | K19: 3355 | L19: =+I19-J19-K19 -> 0
A20: 4 | B20: =IF(Master!$B20=0,"",Master!$B20) -> Soils and Structures | D20: =IF(Master!$D20=0,"",Master!$D20) -> 6480 Grand Haven Rd Muskegon MI 49441 | E20: =IF(Master!$E20=0,"",Master!$E20) -> 1-800-933-3959 | F20: =IF(Master!$F20=0,"",Master!$F20) -> Engineering Services | G20: =Master!G20 -> 15930 | H20: ='Draw 3'!H20 -> 0 | I20: =+G20+H20 -> 15930 | J20: ='Draw 3'!J20+'Draw 3'!K20 -> 2082.5 | K20: 453 | L20: =+I20-J20-K20 -> 13394.5
A21: 5 | B21: =IF(Master!$B21=0,"",Master!$B21) | D21: =IF(Master!$D21=0,"",Master!$D21) | E21: =IF(Master!$E21=0,"",Master!$E21) | F21: =IF(Master!$F21=0,"",Master!$F21) -> Engineering Services | G21: =Master!G21 -> 21742.22 | H21: ='Draw 3'!H21-3355 -> -15150 | I21: =+G21+H21 -> 6592.22 | J21: ='Draw 3'!J21+'Draw 3'!K21 -> 0 | L21: =+I21-J21-K21 -> 6592.22
A22: 6 | B22: =IF(Master!$B22=0,"",Master!$B22) | D22: =IF(Master!$D22=0,"",Master!$D22) | E22: =IF(Master!$E22=0,"",Master!$E22) | F22: =IF(Master!$F22=0,"",Master!$F22) | G22: =Master!G22 -> 0 | H22: ='Draw 3'!H22 -> 0 | I22: =+G22+H22 -> 0 | J22: ='Draw 3'!J22+'Draw 3'!K22 -> 0 | L22: =+I22-J22-K22 -> 0
A23: 7 | B23: =IF(Master!$B23=0,"",Master!$B23) -> Handicap Sign | D23: =IF(Master!$D23=0,"",Master!$D23) -> 1142 Wealthy St., Grand Rapids, MI 49506 | E23: =IF(Master!$E23=0,"",Master!$E23) -> 616-454-9416 | F23: =IF(Master!$F23=0,"",Master!$F23) -> Common Area Improvements | G23: =Master!G23 -> 424.4 | H23: ='Draw 3'!H23 -> 0 | I23: =+G23+H23 -> 424.4 | J23: ='Draw 3'!J23+'Draw 3'!K23 -> 424.4 | L23: =+I23-J23-K23 -> 0
A24: 8 | B24: =IF(Master!$B24=0,"",Master!$B24) -> Rosendall Well Drilling | D24: =IF(Master!$D24=0,"",Master!$D24) -> 4181 Knapp, Grand Rapids, MI 49525 | E24: =IF(Master!$E24=0,"",Master!$E24) -> 616-363-2683 | F24: =IF(Master!$F24=0,"",Master!$F24) -> Common Area Improvements | G24: =Master!G24 -> 47734 | H24: ='Draw 3'!H24 -> 0 | I24: =+G24+H24 -> 47734 | J24: ='Draw 3'!J24+'Draw 3'!K24 -> 47734 | L24: =+I24-J24-K24 -> 0
A25: 9 | B25: =IF(Master!$B25=0,"",Master!$B25) | D25: =IF(Master!$D25=0,"",Master!$D25) | E25: =IF(Master!$E25=0,"",Master!$E25) | F25: =IF(Master!$F25=0,"",Master!$F25) -> Common Area Improvements | G25: =Master!G25 -> 8214.6 | H25: ='Draw 3'!H25 -> 0 | I25: =+G25+H25 -> 8214.6 | J25: ='Draw 3'!J25+'Draw 3'!K25 -> 0 | L25: =+I25-J25-K25 -> 8214.6
A26: 10 | B26: =IF(Master!$B26=0,"",Master!$B26) | D26: =IF(Master!$D26=0,"",Master!$D26) | E26: =IF(Master!$E26=0,"",Master!$E26) | F26: =IF(Master!$F26=0,"",Master!$F26) | G26: =Master!G26 -> 0 | H26: ='Draw 3'!H26 -> 0 | I26: =+G26+H26 -> 0 | J26: ='Draw 3'!J26+'Draw 3'!K26 -> 0 | L26: =+I26-J26-K26 -> 0
A27: 11 | B27: =IF(Master!$B27=0,"",Master!$B27) | D27: =IF(Master!$D27=0,"",Master!$D27) | E27: =IF(Master!$E27=0,"",Master!$E27) | F27: =IF(Master!$F27=0,"",Master!$F27) | G27: =Master!G27 -> 0 | H27: ='Draw 3'!H27 -> 0 | I27: =+G27+H27 -> 0 | J27: ='Draw 3'!J27+'Draw 3'!K27 -> 0 | L27: =+I27-J27-K27 -> 0
A28: 12 | B28: =IF(Master!$B28=0,"",Master!$B28) | D28: =IF(Master!$D28=0,"",Master!$D28) | E28: =IF(Master!$E28=0,"",Master!$E28) | F28: =IF(Master!$F28=0,"",Master!$F28) | G28: =Master!G28 -> 0 | H28: ='Draw 3'!H28 -> 0 | I28: =+G28+H28 -> 0 | J28: ='Draw 3'!J28+'Draw 3'!K28 -> 0 | L28: =+I28-J28-K28 -> 0
A29: 13 | B29: =IF(Master!$B29=0,"",Master!$B29) -> State of Michigan | D29: =IF(Master!$D29=0,"",Master!$D29) -> Lansing, MI 48909 | E29: =IF(Master!$E29=0,"",Master!$E29) | F29: =IF(Master!$F29=0,"",Master!$F29) -> Permits and Fees | G29: =Master!G29 -> 800 | H29: ='Draw 3'!H29 -> 0 | I29: =+G29+H29 -> 800 | J29: ='Draw 3'!J29+'Draw 3'!K29 -> 800 | L29: =+I29-J29-K29 -> 0
A30: 14 | B30: =IF(Master!$B30=0,"",Master!$B30) -> Kent County Health Department | D30: =IF(Master!$D30=0,"",Master!$D30) -> 700 Fuller Ave., Grand Rapids, MI 49503 | E30: =IF(Master!$E30=0,"",Master!$E30) -> 616-632-7100 | F30: =IF(Master!$F30=0,"",Master!$F30) -> Permits and Fees | G30: =Master!G30 -> 2635 | H30: ='Draw 3'!H30 -> 0 | I30: =+G30+H30 -> 2635 | J30: ='Draw 3'!J30+'Draw 3'!K30 -> 2635 | L30: =+I30-J30-K30 -> 0
A31: 15 | B31: =IF(Master!$B31=0,"",Master!$B31) -> Kent County Road Commission | D31: =IF(Master!$D31=0,"",Master!$D31) -> 1500 Scribner, Grand Rapids, MI 49504 | E31: =IF(Master!$E31=0,"",Master!$E31) -> 616-242-6900 | F31: =IF(Master!$F31=0,"",Master!$F31) -> Permits and Fees | G31: =Master!G31 -> 13445 | H31: ='Draw 3'!H31 -> 675 | I31: =+G31+H31 -> 14120 | J31: ='Draw 3'!J31+'Draw 3'!K31 -> 14120 | L31: =+I31-J31-K31 -> 0
